Workbook

Sheet Instructions
B2: PLANIFICATION STRATÉGIQUE — CAMIONS DUBOIS
B3: Guide d'utilisation du classeur de gestion stratégique
B6: 1. OBJECTIF DU FICHIER
B8: But : | C8: Ce fichier est l'outil central de pilotage stratégique de Camions Dubois. Il permet de définir les axes stratégiques, de les transformer en initiatives concrètes, puis de les découper en projets exécutables de 90 jours ou moins.
B9: Utilisateurs cibles : | C9: Président, Direction générale, Équipe de gestion
B10: Fréquence de mise à jour : | C10: Hebdomadaire pour les projets / Trimestrielle pour les initiatives / Annuelle pour les axes
B12: 2. LOGIQUE DE STRUCTURE : AXE → INITIATIVE → PROJET
B14: AXE STRATÉGIQUE | C14: Grand domaine d'orientation de l'entreprise (ex : Exportation, Opérations, RH)
B15: INITIATIVE | C15: Grand projet structurant rattaché à un axe (horizon 2-10 ans)
B16: PROJET 90 JOURS | C16: Tâche concrète et livrable, exécutable en 90 jours ou moins
C17: Chaque projet doit produire un livrable tangible à l'intérieur d'une fenêtre de 90 jours.
B19: 3. RESPONSABLE vs IMPUTABLE (modèle RACI simplifié)
B21: RESPONSABLE (R) | C21: La personne qui FAIT le travail au quotidien. Elle exécute, coordonne, avance le projet.
B22: IMPUTABLE (A) | C22: La personne qui RÉPOND des résultats. Elle n'exécute pas nécessairement, mais doit rendre compte. Il ne peut y avoir qu'UN seul imputable par projet.
C23: Exemple : Responsable = Joël Cartier (mène le projet), Imputable = Jason Dubois (rend compte au président).
B25: 4. DESCRIPTION DES FEUILLES
B27: → Instructions | C27: Cette feuille. Guide de démarrage et référence d'utilisation.
B28: → Axes_Strategiques | C28: Saisir les grands axes stratégiques de l'entreprise. Point de départ de la hiérarchie.
B29: → Initiatives | C29: Définir les initiatives rattachées à chaque axe. Relier via l'ID_Axe.
B30: → Projets_90_Jours | C30: Piloter tous les projets en exécution. Feuille de travail principale de l'équipe.
B31: → Dashboard | C31: Vue globale automatique. Ne rien saisir ici — tout est calculé automatiquement.
B32: → Listes | C32: Listes de référence pour les menus déroulants. Ne pas modifier la structure.
B34: 5. COMMENT UTILISER LE FICHIER
B36: Étape 1 | C36: Ouvrir la feuille Axes_Strategiques et saisir les axes de l'entreprise avec leur horizon et priorité.
B37: Étape 2 | C37: Ouvrir la feuille Initiatives et créer les initiatives. Indiquer l'ID_Axe correspondant.
B38: Étape 3 | C38: Ouvrir la feuille Projets_90_Jours et créer les projets. Indiquer l'ID_Initiative, les dates, le responsable et l'imputable.
B39: Étape 4 | C39: Mettre à jour le statut et l'avancement (%) de chaque projet en cours de semaine.
B40: Étape 5 | C40: Consulter le Dashboard pour une vue globale de l'état stratégique.
B42: 6. LISTES DÉROULANTES
C44: Les colonnes avec listes déroulantes sont identifiées par un menu à la sélection. Cliquer sur la cellule pour voir les options disponibles.
B45: • Horizon | C45: 0-2 ans / 3-5 ans / 5-10 ans
B46: • Priorité | C46: Haute / Moyenne / Basse
B47: • Statut Initiative | C47: Non démarrée / En planification / En cours / En pause / Terminée
B48: • Statut Projet | C48: Non démarré / En cours / À risque / Bloqué / Terminé
B49: • Trimestre | C49: T1 / T2 / T3 / T4
B50: • Responsable | C50: Noms définis dans la feuille Listes — section Personnes
B52: 7. COMMENT LIRE LE DASHBOARD
B54: Indicateurs globaux | C54: Nombre d'axes, initiatives, projets, statuts — calculés automatiquement.
B55: Répartition par horizon | C55: Distribution des projets sur les 3 horizons temporels.
B56: Répartition par statut | C56: Vue rapide des projets actifs, à risque, bloqués ou terminés.
...

Sheet Axes_Strategiques
A2: AXES STRATÉGIQUES — CAMIONS DUBOIS
A4: ID_Axe | B4: Axe_Strategique | C4: Description | D4: Horizon_Principal | E4: Objectif_Global | F4: Priorite | G4: Proprietaire_Axe | H4: Imputable_Axe | I4: Commentaires
A5: AX-01 | B5: Exportation | C5: Développer les marchés d'exportation de véhicules et pièces | D5: 3-5 ans | E5: Accroître les revenus hors-Canada de 20% en 5 ans | F5: Haute | G5: Jason Dubois | H5: Régis Dubois
A6: AX-02 | B6: Opérations | C6: Optimiser les processus de production et de l'atelier | D6: 0-2 ans | E6: Réduire les délais de production de 15% et améliorer la qualité | F6: Haute | G6: Joël Cartier | H6: Michael Dubois
A7: AX-03 | B7: Ressources Humaines | C7: Stabiliser et développer la main-d'œuvre spécialisée | D7: 0-2 ans | E7: Réduire le roulement à moins de 10% et combler les postes clés | F7: Haute | G7: Régis Dubois | H7: Jason Dubois
A8: AX-04 | B8: Technologie & Systèmes | C8: Moderniser les outils de gestion et de suivi | D8: 0-2 ans | E8: Déployer un système de gestion visuelle complet d'ici 18 mois | F8: Moyenne | G8: Michael Dubois | H8: Jason Dubois
A9: AX-05 | B9: Finance | C9: Renforcer la solidité financière et la prévisibilité | D9: 3-5 ans | E9: Améliorer la marge nette de 3 points en 5 ans | F9: Moyenne | G9: Régis Dubois | H9: Jason Dubois
A10: AX-06 | B10: Vente & Développement | C10: Croître les revenus et diversifier la clientèle | D10: 3-5 ans | E10: Augmenter le carnet de commandes de 25% en 3 ans | F10: Haute | G10: Jason Dubois | H10: Régis Dubois

Sheet Initiatives
A2: INITIATIVES STRATÉGIQUES — CAMIONS DUBOIS
A4: ID_Initiative | B4: ID_Axe | C4: Axe_Strategique | D4: Nom_Initiative | E4: Description_Initiative | F4: Horizon | G4: Annee_Cible | H4: Resultat_Attendu | I4: KPI_Principal | J4: Responsable_Initiative | K4: Imputable_Initiative | L4: Statut_Initiative | M4: Priorite | N4: Commentaires
A5: IN-01 | B5: AX-01 | C5: Exportation | D5: Exportation camions usagés — Mexique | E5: Développer le marché mexicain pour la vente de camions d'occasion certifiés | F5: 3-5 ans | G5: 2027 | H5: Vendre 25 unités/an au Mexique | I5: Nb unités vendues Mexique/an | J5: Jason Dubois | K5: Régis Dubois | L5: En planification | M5: Haute
A6: IN-02 | B6: AX-01 | C6: Exportation | D6: Exportation pièces usagées — Amér. Centrale | E6: Créer un canal de distribution de pièces usagées en Amérique Centrale | F6: 3-5 ans | G6: 2028 | H6: 500K$ revenus annuels pièces exportées | I6: Revenus pièces exportées ($) | J6: Joël Cartier | K6: Jason Dubois | L6: Non démarrée | M6: Haute
A7: IN-03 | B7: AX-02 | C7: Opérations | D7: Gestion visuelle atelier | E7: Implanter un système de gestion visuelle complet dans l'atelier de production | F7: 0-2 ans | G7: 2025 | H7: Réduire le temps de recherche d'information de 30% | I7: Temps moyen résolution problème | J7: Michael Dubois | K7: Joël Cartier | L7: En cours | M7: Haute
A8: IN-04 | B8: AX-02 | C8: Opérations | D8: Standardisation production camions à eau | E8: Développer et déployer des gammes de fabrication standardisées pour les camions à eau | F8: 0-2 ans | G8: 2025 | H8: Réduire la variabilité de 25% et le cycle de production de 15% | I8: Durée moyenne cycle production | J8: Joël Cartier | K8: Michael Dubois | L8: En planification | M8: Haute
A9: IN-05 | B9: AX-03 | C9: Ressources Humaines | D9: Recrutement mécaniciens diesel | E9: Combler les postes de mécaniciens diesel qualifiés et réduire la dépendance aux sous-traitants | F9: 0-2 ans | G9: 2025 | H9: Embaucher 4 mécaniciens qualifiés d'ici 18 mois | I9: Postes comblés / Postes cibles | J9: Régis Dubois | K9: Jason Dubois | L9: En cours | M9: Haute
A10: IN-06 | B10: AX-03 | C10: Ressources Humaines | D10: Programme de rétention & développement | E10: Mettre en place un programme structuré de rétention et d'évolution des employés clés | F10: 0-2 ans | G10: 2026 | H10: Réduire le taux de roulement à <10% | I10: Taux de roulement annuel (%) | J10: Régis Dubois | K10: Jason Dubois | L10: Non démarrée | M10: Moyenne
A11: IN-07 | B11: AX-04 | C11: Technologie & Systèmes | D11: Déploiement écrans de suivi | E11: Installer des écrans de suivi de production dans tous les secteurs de l'atelier | F11: 0-2 ans | G11: 2025 | H11: 100% des postes de travail couverts par un écran de suivi | I11: % postes avec écran actif | J11: Michael Dubois | K11: Joël Cartier | L11: En cours | M11: Haute
A12: IN-08 | B12: AX-04 | C12: Technologie & Systèmes | D12: Tableau de bord KPI direction | E12: Créer un tableau de bord numérique de suivi des KPIs pour la direction | F12: 0-2 ans | G12: 2025 | H12: Dashboard opérationnel mis à jour en temps réel | I12: Disponibilité dashboard (%) | J12: Michael Dubois | K12: Jason Dubois | L12: En planification | M12: Moyenne
A13: IN-09 | B13: AX-06 | C13: Vente & Développement | D13: Développement clientèle municipale | E13: Cibler et développer le segment des municipalités pour les camions à eau et de service | F13: 3-5 ans | G13: 2027 | H13: 10 nouveaux contrats municipaux en 3 ans | I13: Nb contrats municipaux signés | J13: Jason Dubois | K13: Régis Dubois | L13: Non démarrée | M13: Haute
A14: IN-10 | B14: AX-05 | C14: Finance | D14: Tableau de bord financier mensuel | E14: Mettre en place un tableau de bord financier mensuel avec indicateurs clés | F14: 0-2 ans | G14: 2025 | H14: Rapport financier mensuel disponible avant le 10 du mois | I14: Délai livraison rapport (jours) | J14: Régis Dubois | K14: Jason Dubois | L14: En planification | M14: Moyenne

Sheet Projets_90_Jours
A2: PROJETS 90 JOURS — CAMIONS DUBOIS
A4: ID_Projet | B4: ID_Initiative | C4: Nom_Initiative | D4: Axe_Strategique | E4: Nom_Projet | F4: Description_Projet | G4: Horizon | H4: Trimestre | I4: Date_Debut | J4: Date_Fin | K4: Duree_Jours | L4: Responsable | M4: Imputable | N4: Support | O4: Priorite | P4: Statut | Q4: Objectif_90_Jours | R4: Livrable_1 | S4: Livrable_2 | T4: Livrable_3 | U4: KPI_1 | V4: KPI_2 | W4: KPI_3 | X4: Budget_Estime | Y4: Avancement_% | Z4: Risques_Blocages | AA4: Prochaine_Etape | AB4: Commentaires
A5: PR-01 | B5: IN-01 | C5: Export camions — Mexique | D5: Exportation | E5: Étude de marché Mexique | F5: Analyser la demande, les réglementations et les concurrents sur le marché mexicain | G5: 3-5 ans | H5: T2 | I5: 45748 | J5: 45822 | K5: =IF(AND(I5<>"",J5<>""),J5-I5,"") | L5: Jason Dubois | M5: Régis Dubois | N5: Consultant | O5: Haute | P5: Terminé | Q5: Produire un rapport d'analyse de marché mexicain complet | R5: Rapport analyse concurrence | S5: Carte réglementation importation | T5: Liste 5 clients cibles | U5: Date remise rapport | V5: Nb contacts établis | W5: Nb barrières identifiées | X5: 15000 | Y5: 1 | Z5: Délais douaniers difficiles à évaluer | AA5: Présenter rapport à direction
A6: PR-02 | B6: IN-01 | C6: Export camions — Mexique | D6: Exportation | E6: Mission prospection Mexique | F6: Effectuer une mission terrain au Mexique pour rencontrer des distributeurs potentiels | G6: 3-5 ans | H6: T3 | I6: 45839 | J6: 45915 | K6: =IF(AND(I6<>"",J6<>""),J6-I6,"") | L6: Jason Dubois | M6: Régis Dubois | N6: Consultant | O6: Haute | P6: En cours | Q6: Établir 3 partenariats distributeurs au Mexique | R6: 3 lettres d'intention signées | S6: Plan de suivi distributeurs | T6: Calendrier visites Q4 | U6: Nb distributeurs rencontrés | V6: Nb LOI signées | W6: Pipeline unités estimé | X6: 25000 | Y6: 0.35 | Z6: Visas et logistique à confirmer | AA6: Confirmer rendez-vous avec 5 distributeurs
A7: PR-03 | B7: IN-02 | C7: Export pièces — Amér. Centrale | D7: Exportation | E7: Cartographie marchés Amér. Centrale | F7: Identifier les marchés prioritaires et les canaux de distribution en Amérique Centrale | G7: 3-5 ans | H7: T4 | I7: 45931 | J7: 46006 | K7: =IF(AND(I7<>"",J7<>""),J7-I7,"") | L7: Joël Cartier | M7: Jason Dubois | N7: À définir | O7: Haute | P7: Non démarré | Q7: Identifier 3 marchés cibles et 5 contacts clés en Amérique Centrale | R7: Rapport cartographie marchés | S7: Liste contacts distributeurs | T7: Budget prospection 2026 | U7: Nb marchés évalués | V7: Nb contacts qualifiés | W7: Revenus potentiels estimés ($) | X7: 8000 | Y7: 0 | Z7: Ressources à identifier | AA7: Lancer appel d'offres consultant
A8: PR-04 | B8: IN-03 | C8: Gestion visuelle atelier | D8: Opérations | E8: Audit visuel atelier complet | F8: Réaliser un audit de l'état actuel de la gestion visuelle dans l'atelier | G8: 0-2 ans | H8: T1 | I8: 45672 | J8: 45731 | K8: =IF(AND(I8<>"",J8<>""),J8-I8,"") | L8: Michael Dubois | M8: Joël Cartier | N8: Consultant | O8: Haute | P8: Terminé | Q8: Produire un rapport d'audit avec carte des lacunes visuelles | R8: Rapport audit complet | S8: Carte des zones critiques | T8: Plan d'action priorisé | U8: Score audit visuel (/100) | V8: Nb zones auditées | W8: Nb opportunités identifiées | X8: 5000 | Y8: 1 | AA8: Démarrer implantation zones prioritaires
A9: PR-05 | B9: IN-03 | C9: Gestion visuelle atelier | D9: Opérations | E9: Implantation écrans zone assemblage | F9: Installer et configurer les écrans de suivi de production dans la zone assemblage | G9: 0-2 ans | H9: T2 | I9: 45748 | J9: 45828 | K9: =IF(AND(I9<>"",J9<>""),J9-I9,"") | L9: Michael Dubois | M9: Joël Cartier | N9: Joël Cartier | O9: Haute | P9: En cours | Q9: 100% de la zone assemblage couverte par les écrans de suivi | R9: 4 écrans installés et actifs | S9: Formation équipe complétée | T9: Procédures utilisation documentées | U9: Nb écrans actifs | V9: % opérateurs formés | W9: Délai moyen affichage info (s) | X9: 12000 | Y9: 0.6 | Z9: Intégration avec système ERP à valider | AA9: Finaliser câblage zone 3
A10: PR-06 | B10: IN-04 | C10: Standardisation production | D10: Opérations | E10: Cartographie processus production camion eau | F10: Documenter le processus actuel de fabrication d'un camion à eau de A à Z | G10: 0-2 ans | H10: T1 | I10: 45689 | J10: 45757 | K10: =IF(AND(I10<>"",J10<>""),J10-I10,"") | L10: Joël Cartier | M10: Michael Dubois | O10: Haute | P10: Terminé | Q10: Cartographie complète du flux de valeur camion eau | R10: VSM état actuel | S10: Liste des gaspillages identifiés | T10: Rapport recommandations | U10: Durée cycle documentée (jours) | V10: Nb étapes documentées | W10: Nb gaspillages identifiés | X10: 3000 | Y10: 1 | AA10: Lancer projet standardisation étape 1
A11: PR-07 | B11: IN-04 | C11: Standardisation production | D11: Opérations | E11: Création gammes de fabrication std. | F11: Rédiger les gammes de fabrication standardisées pour les 5 sous-ensembles critiques | G11: 0-2 ans | H11: T2 | I11: 45778 | J11: 45863 | K11: =IF(AND(I11<>"",J11<>""),J11-I11,"") | L11: Joël Cartier | M11: Michael Dubois | O11: Haute | P11: En cours | Q11: 5 gammes de fabrication validées et déployées en atelier | R11: 5 gammes rédigées et validées | S11: Fiches poste mises à jour | T11: Formation compagnons complétée | U11: Nb gammes déployées | V11: % conformité gammes | W11: Durée cycle (avant vs après) | X11: 4000 | Y11: 0.45 | Z11: Résistance au changement possible | AA11: Valider gamme sous-ensemble 3 avec Joël
A12: PR-08 | B12: IN-05 | C12: Recrutement mécaniciens diesel | D12: Ressources Humaines | E12: Campagne recrutement mécaniciens | F12: Lancer une campagne de recrutement ciblée pour 4 postes de mécaniciens diesel | G12: 0-2 ans | H12: T2 | I12: 45748 | J12: 45838 | K12: =IF(AND(I12<>"",J12<>""),J12-I12,"") | L12: Régis Dubois | M12: Jason Dubois | O12: Haute | P12: En cours | Q12: Recevoir 20 candidatures qualifiées et compléter 4 entrevues finales | R12: Affichages actifs sur 3 plateformes | S12: 20 candidatures reçues | T12: 4 entrevues finales planifiées | U12: Nb candidatures reçues | V12: Nb entrevues complétées | W12: Nb offres acceptées | X12: 8000 | Y12: 0.55 | Z12: Pénurie de main-d'oeuvre dans le secteur | AA12: Contacter école de mécanique St-Hyacinthe
A13: PR-09 | B13: IN-05 | C13: Recrutement mécaniciens diesel | D13: Ressources Humaines | E13: Onboarding mécaniciens — programme 30 jours | F13: Créer et déployer un programme d'intégration structuré de 30 jours | G13: 0-2 ans | H13: T3 | I13: 45839 | J13: 45900 | K13: =IF(AND(I13<>"",J13<>""),J13-I13,"") | L13: Régis Dubois | M13: Jason Dubois | N13: Joël Cartier | O13: Moyenne | P13: Non démarré | Q13: Programme onboarding 30j documenté et premier mécanicien intégré avec succès | R13: Guide onboarding rédigé | S13: Calendrier 30j créé | T13: 1er mécanicien intégré | U13: Taux rétention 90j (%) | V13: Score satisfaction employé onboarding | W13: Nb compétences maîtrisées J30 | X13: 2000 | Y13: 0 | Z13: Disponibilité superviseur pour accompagnement | AA13: Rédiger programme semaine 1
A14: PR-10 | B14: IN-07 | C14: Déploiement écrans suivi | D14: Technologie & Systèmes | E14: Spécifications techniques écrans | F14: Définir les spécifications et sélectionner le fournisseur d'écrans de suivi | G14: 0-2 ans | H14: T1 | I14: 45672 | J14: 45747 | K14: =IF(AND(I14<>"",J14<>""),J14-I14,"") | L14: Michael Dubois | M14: Joël Cartier | O14: Haute | P14: Terminé | Q14: Fournisseur sélectionné et bon de commande émis | R14: Cahier des charges rédigé | S14: 3 soumissions reçues | T14: Fournisseur choisi + PO émis | U14: Nb soumissions évaluées | V14: Score évaluation fournisseur (/10) | W14: Délai livraison confirmé | X14: 55000 | Y14: 1 | AA14: Coordonner installation avec fournisseur
A15: PR-11 | B15: IN-08 | C15: Dashboard KPI direction | D15: Technologie & Systèmes | E15: Design et prototype dashboard direction | F15: Concevoir la structure et les KPIs du tableau de bord de direction | G15: 0-2 ans | H15: T2 | I15: 45762 | J15: 45838 | K15: =IF(AND(I15<>"",J15<>""),J15-I15,"") | L15: Michael Dubois | M15: Jason Dubois | N15: Régis Dubois | O15: Moyenne | P15: En cours | Q15: Prototype validé par la direction avec 10 KPIs confirmés | R15: Prototype Excel/Power BI livré | S15: 10 KPIs validés par direction | T15: Plan migration données défini | U15: Score validation direction (/10) | V15: Nb KPIs intégrés | W15: Nb sources de données connectées | X15: 6000 | Y15: 0.3 | Z15: Accès aux données systèmes à confirmer | AA15: Présenter prototype V1 à Jason
A16: PR-12 | B16: IN-09 | C16: Développement clientèle municipale | D16: Vente & Développement | E16: Cartographie clients municipaux Québec | F16: Identifier et prioriser les 50 municipalités cibles pour la vente de camions à eau | G16: 3-5 ans | H16: T3 | I16: 45839 | J16: 45915 | K16: =IF(AND(I16<>"",J16<>""),J16-I16,"") | L16: Jason Dubois | M16: Régis Dubois | N16: Consultant | O16: Haute | P16: Non démarré | Q16: Liste de 50 municipalités cibles priorisées avec contacts identifiés | R16: Base de données 50 municip. cibles | S16: 50 contacts clés identifiés | T16: Plan approche muni. Q4 | U16: Nb municip. contactées | V16: Nb rendez-vous confirmés | W16: Pipeline estimé ($) | X16: 5000 | Y16: 0 | AA16: Démarrer recherche MAMH
A17: PR-13 | B17: IN-10 | C17: Dashboard financier mensuel | D17: Finance | E17: Rapport financier mensuel — format | F17: Concevoir et valider le format et les indicateurs du rapport financier mensuel | G17: 0-2 ans | H17: T2 | I17: 45748 | J17: 45807 | K17: =IF(AND(I17<>"",J17<>""),J17-I17,"") | L17: Régis Dubois | M17: Jason Dubois | O17: Moyenne | P17: En cours | Q17: Format du rapport financier mensuel approuvé par direction | R17: Modèle rapport financier Excel | S17: 10 KPIs financiers définis | T17: Procédure production rapport | U17: Date remise premier rapport | V17: Nb KPIs financiers validés | W17: Délai production rapport (h) | X17: 3000 | Y17: 0.5 | Z17: Accès aux données comptables | AA17: Valider liste KPIs avec Régis
K18: =IF(AND(I18<>"",J18<>""),J18-I18,"")
K19: =IF(AND(I19<>"",J19<>""),J19-I19,"")
K20: =IF(AND(I20<>"",J20<>""),J20-I20,"")
K21: =IF(AND(I21<>"",J21<>""),J21-I21,"")
K22: =IF(AND(I22<>"",J22<>""),J22-I22,"")
K23: =IF(AND(I23<>"",J23<>""),J23-I23,"")
K24: =IF(AND(I24<>"",J24<>""),J24-I24,"")
K25: =IF(AND(I25<>"",J25<>""),J25-I25,"")
K26: =IF(AND(I26<>"",J26<>""),J26-I26,"")
K27: =IF(AND(I27<>"",J27<>""),J27-I27,"")
K28: =IF(AND(I28<>"",J28<>""),J28-I28,"")
K29: =IF(AND(I29<>"",J29<>""),J29-I29,"")
... K104: =IF(AND(I104<>"",J104<>""),J104-I104,"")

Sheet Dashboard
B2: TABLEAU DE BORD STRATÉGIQUE — CAMIONS DUBOIS | P2: Statut | Q2: Nb
P3: Non démarré | Q3: =COUNTIF(Projets_90_Jours!P5:P104,"Non démarré")
B4: Mise à jour automatique — Ne pas modifier cette feuille directement | P4: En cours | Q4: =COUNTIF(Projets_90_Jours!P5:P104,"En cours")
P5: À risque | Q5: =COUNTIF(Projets_90_Jours!P5:P104,"À risque")
B6: A. INDICATEURS GLOBAUX | G6: G. PROCHAINES ÉCHÉANCES (top 10) | P6: Bloqué | Q6: =COUNTIF(Projets_90_Jours!P5:P104,"Bloqué")
P7: Terminé | Q7: =COUNTIF(Projets_90_Jours!P5:P104,"Terminé")
B8: Axes stratégiques | D8: Initiatives | G8: Nom du projet | J8: Date fin | L8: Statut
B9: =COUNTA(Axes_Strategiques!A5:A24) | D9: =COUNTA(Initiatives!A5:A54) | G9: Projets actifs (hors Terminé) triés par date de fin :
G10: =IFERROR(INDEX(Projets_90_Jours!E$5:E$104,MATCH(SMALL(IF(Projets_90_Jours!P$5:P$104<>"Terminé",IF(Projets_90_Jours!J$5:J$104<>"",Projets_90_Jours!J$5:J$104)),1),Projets_90_Jours!J$5:J$104,0)),"") | J10: =IFERROR(SMALL(IF(Projets_90_Jours!P$5:P$104<>"Terminé",IF(Projets_90_Jours!J$5:J$104<>"",Projets_90_Jours!J$5:J$104)),1),"") | L10: =IFERROR(INDEX(Projets_90_Jours!P$5:P$104,MATCH(SMALL(IF(Projets_90_Jours!P$5:P$104<>"Terminé",IF(Projets_90_Jours!J$5:J$104<>"",Projets_90_Jours!J$5:J$104)),1),Projets_90_Jours!J$5:J$104,0)),"")
B11: Projets total | D11: Projets actifs | G11: =IFERROR(INDEX(Projets_90_Jours!E$5:E$104,MATCH(SMALL(IF(Projets_90_Jours!P$5:P$104<>"Terminé",IF(Projets_90_Jours!J$5:J$104<>"",Projets_90_Jours!J$5:J$104)),2),Projets_90_Jours!J$5:J$104,0)),"") | J11: =IFERROR(SMALL(IF(Projets_90_Jours!P$5:P$104<>"Terminé",IF(Projets_90_Jours!J$5:J$104<>"",Projets_90_Jours!J$5:J$104)),2),"") | L11: =IFERROR(INDEX(Projets_90_Jours!P$5:P$104,MATCH(SMALL(IF(Projets_90_Jours!P$5:P$104<>"Terminé",IF(Projets_90_Jours!J$5:J$104<>"",Projets_90_Jours!J$5:J$104)),2),Projets_90_Jours!J$5:J$104,0)),"")
B12: =COUNTA(Projets_90_Jours!A5:A104) | D12: =COUNTIF(Projets_90_Jours!P5:P104,"En cours") | G12: =IFERROR(INDEX(Projets_90_Jours!E$5:E$104,MATCH(SMALL(IF(Projets_90_Jours!P$5:P$104<>"Terminé",IF(Projets_90_Jours!J$5:J$104<>"",Projets_90_Jours!J$5:J$104)),3),Projets_90_Jours!J$5:J$104,0)),"") | J12: =IFERROR(SMALL(IF(Projets_90_Jours!P$5:P$104<>"Terminé",IF(Projets_90_Jours!J$5:J$104<>"",Projets_90_Jours!J$5:J$104)),3),"") | L12: =IFERROR(INDEX(Projets_90_Jours!P$5:P$104,MATCH(SMALL(IF(Projets_90_Jours!P$5:P$104<>"Terminé",IF(Projets_90_Jours!J$5:J$104<>"",Projets_90_Jours!J$5:J$104)),3),Projets_90_Jours!J$5:J$104,0)),"")
G13: =IFERROR(INDEX(Projets_90_Jours!E$5:E$104,MATCH(SMALL(IF(Projets_90_Jours!P$5:P$104<>"Terminé",IF(Projets_90_Jours!J$5:J$104<>"",Projets_90_Jours!J$5:J$104)),4),Projets_90_Jours!J$5:J$104,0)),"") | J13: =IFERROR(SMALL(IF(Projets_90_Jours!P$5:P$104<>"Terminé",IF(Projets_90_Jours!J$5:J$104<>"",Projets_90_Jours!J$5:J$104)),4),"") | L13: =IFERROR(INDEX(Projets_90_Jours!P$5:P$104,MATCH(SMALL(IF(Projets_90_Jours!P$5:P$104<>"Terminé",IF(Projets_90_Jours!J$5:J$104<>"",Projets_90_Jours!J$5:J$104)),4),Projets_90_Jours!J$5:J$104,0)),"")
B14: Projets terminés | D14: Projets à risque | G14: =IFERROR(INDEX(Projets_90_Jours!E$5:E$104,MATCH(SMALL(IF(Projets_90_Jours!P$5:P$104<>"Terminé",IF(Projets_90_Jours!J$5:J$104<>"",Projets_90_Jours!J$5:J$104)),5),Projets_90_Jours!J$5:J$104,0)),"") | J14: =IFERROR(SMALL(IF(Projets_90_Jours!P$5:P$104<>"Terminé",IF(Projets_90_Jours!J$5:J$104<>"",Projets_90_Jours!J$5:J$104)),5),"") | L14: =IFERROR(INDEX(Projets_90_Jours!P$5:P$104,MATCH(SMALL(IF(Projets_90_Jours!P$5:P$104<>"Terminé",IF(Projets_90_Jours!J$5:J$104<>"",Projets_90_Jours!J$5:J$104)),5),Projets_90_Jours!J$5:J$104,0)),"")
B15: =COUNTIF(Projets_90_Jours!P5:P104,"Terminé") | D15: =COUNTIF(Projets_90_Jours!P5:P104,"À risque") | G15: =IFERROR(INDEX(Projets_90_Jours!E$5:E$104,MATCH(SMALL(IF(Projets_90_Jours!P$5:P$104<>"Terminé",IF(Projets_90_Jours!J$5:J$104<>"",Projets_90_Jours!J$5:J$104)),6),Projets_90_Jours!J$5:J$104,0)),"") | J15: =IFERROR(SMALL(IF(Projets_90_Jours!P$5:P$104<>"Terminé",IF(Projets_90_Jours!J$5:J$104<>"",Projets_90_Jours!J$5:J$104)),6),"") | L15: =IFERROR(INDEX(Projets_90_Jours!P$5:P$104,MATCH(SMALL(IF(Projets_90_Jours!P$5:P$104<>"Terminé",IF(Projets_90_Jours!J$5:J$104<>"",Projets_90_Jours!J$5:J$104)),6),Projets_90_Jours!J$5:J$104,0)),"")
G16: =IFERROR(INDEX(Projets_90_Jours!E$5:E$104,MATCH(SMALL(IF(Projets_90_Jours!P$5:P$104<>"Terminé",IF(Projets_90_Jours!J$5:J$104<>"",Projets_90_Jours!J$5:J$104)),7),Projets_90_Jours!J$5:J$104,0)),"") | J16: =IFERROR(SMALL(IF(Projets_90_Jours!P$5:P$104<>"Terminé",IF(Projets_90_Jours!J$5:J$104<>"",Projets_90_Jours!J$5:J$104)),7),"") | L16: =IFERROR(INDEX(Projets_90_Jours!P$5:P$104,MATCH(SMALL(IF(Projets_90_Jours!P$5:P$104<>"Terminé",IF(Projets_90_Jours!J$5:J$104<>"",Projets_90_Jours!J$5:J$104)),7),Projets_90_Jours!J$5:J$104,0)),"")
B17: Projets bloqués | D17: Durée > 90 jours | G17: =IFERROR(INDEX(Projets_90_Jours!E$5:E$104,MATCH(SMALL(IF(Projets_90_Jours!P$5:P$104<>"Terminé",IF(Projets_90_Jours!J$5:J$104<>"",Projets_90_Jours!J$5:J$104)),8),Projets_90_Jours!J$5:J$104,0)),"") | J17: =IFERROR(SMALL(IF(Projets_90_Jours!P$5:P$104<>"Terminé",IF(Projets_90_Jours!J$5:J$104<>"",Projets_90_Jours!J$5:J$104)),8),"") | L17: =IFERROR(INDEX(Projets_90_Jours!P$5:P$104,MATCH(SMALL(IF(Projets_90_Jours!P$5:P$104<>"Terminé",IF(Projets_90_Jours!J$5:J$104<>"",Projets_90_Jours!J$5:J$104)),8),Projets_90_Jours!J$5:J$104,0)),"")
B18: =COUNTIF(Projets_90_Jours!P5:P104,"Bloqué") | D18: =COUNTIF(Projets_90_Jours!K5:K104,">90") | G18: =IFERROR(INDEX(Projets_90_Jours!E$5:E$104,MATCH(SMALL(IF(Projets_90_Jours!P$5:P$104<>"Terminé",IF(Projets_90_Jours!J$5:J$104<>"",Projets_90_Jours!J$5:J$104)),9),Projets_90_Jours!J$5:J$104,0)),"") | J18: =IFERROR(SMALL(IF(Projets_90_Jours!P$5:P$104<>"Terminé",IF(Projets_90_Jours!J$5:J$104<>"",Projets_90_Jours!J$5:J$104)),9),"") | L18: =IFERROR(INDEX(Projets_90_Jours!P$5:P$104,MATCH(SMALL(IF(Projets_90_Jours!P$5:P$104<>"Terminé",IF(Projets_90_Jours!J$5:J$104<>"",Projets_90_Jours!J$5:J$104)),9),Projets_90_Jours!J$5:J$104,0)),"")
G19: =IFERROR(INDEX(Projets_90_Jours!E$5:E$104,MATCH(SMALL(IF(Projets_90_Jours!P$5:P$104<>"Terminé",IF(Projets_90_Jours!J$5:J$104<>"",Projets_90_Jours!J$5:J$104)),10),Projets_90_Jours!J$5:J$104,0)),"") | J19: =IFERROR(SMALL(IF(Projets_90_Jours!P$5:P$104<>"Terminé",IF(Projets_90_Jours!J$5:J$104<>"",Projets_90_Jours!J$5:J$104)),10),"") | L19: =IFERROR(INDEX(Projets_90_Jours!P$5:P$104,MATCH(SMALL(IF(Projets_90_Jours!P$5:P$104<>"Terminé",IF(Projets_90_Jours!J$5:J$104<>"",Projets_90_Jours!J$5:J$104)),10),Projets_90_Jours!J$5:J$104,0)),"")
B21: B. RÉPARTITION PAR HORIZON | G21: H. RÉSUMÉ INITIATIVES & PROJETS PAR AXE
B23: Projets 0-2 ans | E23: =COUNTIF(Projets_90_Jours!G5:G104,"0-2 ans") | G23: Axe Stratégique | J23: Initiatives | L23: Projets
B24: Projets 3-5 ans | E24: =COUNTIF(Projets_90_Jours!G5:G104,"3-5 ans") | G24: Exportation | J24: =COUNTIF(Initiatives!C5:C54,"Exportation") | L24: =COUNTIF(Projets_90_Jours!D5:D104,"Exportation")
B25: Projets 5-10 ans | E25: =COUNTIF(Projets_90_Jours!G5:G104,"5-10 ans") | G25: Opérations | J25: =COUNTIF(Initiatives!C5:C54,"Opérations") | L25: =COUNTIF(Projets_90_Jours!D5:D104,"Opérations")
B26: TOTAL | E26: =E23+E24+E25 | G26: Ressources Humaines | J26: =COUNTIF(Initiatives!C5:C54,"Ressources Humaines") | L26: =COUNTIF(Projets_90_Jours!D5:D104,"Ressources Humaines")
G27: Technologie & Systèmes | J27: =COUNTIF(Initiatives!C5:C54,"Technologie & Systèmes") | L27: =COUNTIF(Projets_90_Jours!D5:D104,"Technologie & Systèmes")
B28: C. RÉPARTITION PAR PRIORITÉ | G28: Finance | J28: =COUNTIF(Initiatives!C5:C54,"Finance") | L28: =COUNTIF(Projets_90_Jours!D5:D104,"Finance")
G29: Vente & Développement | J29: =COUNTIF(Initiatives!C5:C54,"Vente & Développement") | L29: =COUNTIF(Projets_90_Jours!D5:D104,"Vente & Développement")
B30: Priorité Haute | E30: =COUNTIF(Projets_90_Jours!O5:O104,"Haute")
B31: Priorité Moyenne | E31: =COUNTIF(Projets_90_Jours!O5:O104,"Moyenne")
B32: Priorité Basse | E32: =COUNTIF(Projets_90_Jours!O5:O104,"Basse")
B34: D. RÉPARTITION PAR STATUT
B36: Non démarrés | E36: =COUNTIF(Projets_90_Jours!P5:P104,"Non démarré")
B37: En cours | E37: =COUNTIF(Projets_90_Jours!P5:P104,"En cours")
B38: À risque | E38: =COUNTIF(Projets_90_Jours!P5:P104,"À risque")
B39: Bloqués | E39: =COUNTIF(Projets_90_Jours!P5:P104,"Bloqué")
B40: Terminés | E40: =COUNTIF(Projets_90_Jours!P5:P104,"Terminé")
B42: E. PROJETS PAR AXE STRATÉGIQUE
B44: Exportation | E44: =COUNTIF(Projets_90_Jours!D5:D104,"Exportation")
B45: Opérations | E45: =COUNTIF(Projets_90_Jours!D5:D104,"Opérations")
B46: Ressources Humaines | E46: =COUNTIF(Projets_90_Jours!D5:D104,"Ressources Humaines")
B47: Technologie & Systèmes | E47: =COUNTIF(Projets_90_Jours!D5:D104,"Technologie & Systèmes")
...

Sheet Listes
A1: Horizons | B1: Priorités | C1: Statuts_Initiatives | D1: Statuts_Projets | E1: Personnes | F1: Trimestres | G1: Statuts_Projets_Court
A2: 0-2 ans | B2: Haute | C2: Non démarrée | D2: Non démarré | E2: Jason Dubois | F2: T1 | G2: Non démarré
A3: 3-5 ans | B3: Moyenne | C3: En planification | D3: En cours | E3: Régis Dubois | F3: T2 | G3: En cours
A4: 5-10 ans | B4: Basse | C4: En cours | D4: À risque | E4: Michael Dubois | F4: T3 | G4: À risque
C5: En pause | D5: Bloqué | E5: Joël Cartier | F5: T4 | G5: Bloqué
C6: Terminée | D6: Terminé | E6: Consultant | G6: Terminé
E7: À définir
E8: Direction
E9: RH
A12: ⚠ Ne pas modifier la structure de cette feuille (lignes/colonnes).
A13: Pour ajouter une personne, ajouter une ligne dans la colonne E.
